WARNING: Ignoring invalid distribution -erminado (/mnt/home/n9455647/.conda/envs/conda_test/lib/python3.8/site-packages)
WARNING: Ignoring invalid distribution -cipy (/mnt/home/n9455647/.conda/envs/conda_test/lib/python3.8/site-packages)
/home/n9455647/.conda/envs/conda_test/lib/python3.8/site-packages/pyAgrum/lib/notebook.py:1312: UserWarning: 
  ** pyAgrum.lib.notebook has to be imported from an IPython's instance (mainly notebook).
  
  warnings.warn("""
RuntimeError: module compiled against API version 0xf but this version of numpy is 0xe
Traceback (most recent call last):
  File "/home/n9455647/.conda/envs/conda_test/lib/python3.8/site-packages/pandas/core/indexes/base.py", line 2891, in get_loc
    return self._engine.get_loc(casted_key)
  File "pandas/_libs/index.pyx", line 70, in pandas._libs.index.IndexEngine.get_loc
  File "pandas/_libs/index.pyx", line 101, in pandas._libs.index.IndexEngine.get_loc
  File "pandas/_libs/hashtable_class_helper.pxi", line 1675, in pandas._libs.hashtable.PyObjectHashTable.get_item
  File "pandas/_libs/hashtable_class_helper.pxi", line 1683, in pandas._libs.hashtable.PyObjectHashTable.get_item
KeyError: 'Actual'

The above exception was the direct cause of the following exception:

Traceback (most recent call last):
  File "test_tab_stability.py", line 326, in <module>
    targets = results["Actual"]
  File "/home/n9455647/.conda/envs/conda_test/lib/python3.8/site-packages/pandas/core/frame.py", line 2902, in __getitem__
    indexer = self.columns.get_loc(key)
  File "/home/n9455647/.conda/envs/conda_test/lib/python3.8/site-packages/pandas/core/indexes/base.py", line 2893, in get_loc
    raise KeyError(key) from err
KeyError: 'Actual'
