WARNING: Ignoring invalid distribution -erminado (/mnt/home/n9455647/.conda/envs/conda_test/lib/python3.8/site-packages)
WARNING: Ignoring invalid distribution -cipy (/mnt/home/n9455647/.conda/envs/conda_test/lib/python3.8/site-packages)
Traceback (most recent call last):
  File "/home/n9455647/.conda/envs/conda_test/lib/python3.8/site-packages/pandas/core/indexes/base.py", line 2891, in get_loc
    return self._engine.get_loc(casted_key)
  File "pandas/_libs/index.pyx", line 70, in pandas._libs.index.IndexEngine.get_loc
  File "pandas/_libs/index.pyx", line 101, in pandas._libs.index.IndexEngine.get_loc
  File "pandas/_libs/hashtable_class_helper.pxi", line 1675, in pandas._libs.hashtable.PyObjectHashTable.get_item
  File "pandas/_libs/hashtable_class_helper.pxi", line 1683, in pandas._libs.hashtable.PyObjectHashTable.get_item
KeyError: 'time:timestamp'

The above exception was the direct cause of the following exception:

Traceback (most recent call last):
  File "optimise_el_params.py", line 195, in <module>
    data = dataset_manager.read_dataset()
  File "/mnt/home/n9455647/full_stability/DatasetManager.py", line 42, in read_dataset
    data[self.timestamp_col] = pd.to_datetime(data[self.timestamp_col])
  File "/home/n9455647/.conda/envs/conda_test/lib/python3.8/site-packages/pandas/core/frame.py", line 2902, in __getitem__
    indexer = self.columns.get_loc(key)
  File "/home/n9455647/.conda/envs/conda_test/lib/python3.8/site-packages/pandas/core/indexes/base.py", line 2893, in get_loc
    raise KeyError(key) from err
KeyError: 'time:timestamp'
