WARNING: Ignoring invalid distribution -erminado (/mnt/home/n9455647/.conda/envs/conda_test/lib/python3.8/site-packages)
WARNING: Ignoring invalid distribution -cipy (/mnt/home/n9455647/.conda/envs/conda_test/lib/python3.8/site-packages)
/home/n9455647/.conda/envs/conda_test/lib/python3.8/site-packages/pyAgrum/lib/notebook.py:1312: UserWarning: 
  ** pyAgrum.lib.notebook has to be imported from an IPython's instance (mainly notebook).
  
  warnings.warn("""
RuntimeError: module compiled against API version 0xf but this version of numpy is 0xe
multiprocessing.pool.RemoteTraceback: 
"""
Traceback (most recent call last):
  File "/home/n9455647/.conda/envs/conda_test/lib/python3.8/multiprocessing/pool.py", line 125, in worker
    result = (True, func(*args, **kwds))
  File "/home/n9455647/.conda/envs/conda_test/lib/python3.8/multiprocessing/pool.py", line 48, in mapstar
    return list(map(*args))
  File "test_el_stability.py", line 450, in linda_eval
    weights, feat_pos = get_linda_features(instance, cls, scaler, dataset_ref, 1, feat_list, 1)
  File "test_el_stability.py", line 259, in get_linda_features
    [bn, inference, infoBN] = generate_BN_explanations(instance, label_lst, feat_list, "Result",
  File "/mnt/home/n9455647/full_stability/learning.py", line 680, in generate_BN_explanations
    os.makedirs(folder_path_permutations, mode=0o755)
  File "/home/n9455647/.conda/envs/conda_test/lib/python3.8/os.py", line 223, in makedirs
    mkdir(name, mode)
FileExistsError: [Errno 17] File exists: '/mnt/home/n9455647/full_stability/bpic2011/logit/prefix_agg/feature_permutations/bpic2011/true_positives/'
"""

The above exception was the direct cause of the following exception:

Traceback (most recent call last):
  File "test_el_stability.py", line 790, in <module>
    stability, avg_dispersal, adj_dispersal = zip(*pool.map(linda_eval, [instance for instance in test_dict]))
  File "/home/n9455647/.conda/envs/conda_test/lib/python3.8/multiprocessing/pool.py", line 364, in map
    return self._map_async(func, iterable, mapstar, chunksize).get()
  File "/home/n9455647/.conda/envs/conda_test/lib/python3.8/multiprocessing/pool.py", line 771, in get
    raise self._value
FileExistsError: [Errno 17] File exists: '/mnt/home/n9455647/full_stability/bpic2011/logit/prefix_agg/feature_permutations/bpic2011/true_positives/'
Exception ignored in: <function Pool.__del__ at 0x2ab1bb29faf0>
Traceback (most recent call last):
  File "/home/n9455647/.conda/envs/conda_test/lib/python3.8/multiprocessing/pool.py", line 268, in __del__
  File "/home/n9455647/.conda/envs/conda_test/lib/python3.8/multiprocessing/queues.py", line 362, in put
AttributeError: 'NoneType' object has no attribute 'dumps'
